<?xml version="1.0" ?>
<robot name="jumping_spider" xmlns:xacro="http://www.ros.org/wiki/xacro">

<xacro:include filename="$(find jumping_spider_description)/urdf/materials.xacro" />
<xacro:include filename="$(find jumping_spider_description)/urdf/jumping_spider.trans" />
<link name="base_link">
  <inertial>
    <origin xyz="-0.06080773547952831 -0.0005033531810570811 -0.018253570312340286" rpy="0 0 0"/>
    <mass value="8.080621198047027"/>
    <inertia ixx="0.331955" iyy="0.488395" izz="0.702591" ixy="-0.000728" iyz="0.000368" ixz="0.042735"/>
  </inertial>
  <visual>
    <origin xyz="0 0 0" rpy="0 0 0"/>
    <geometry>
      <mesh filename="package://jumping_spider_description/meshes/base_link.stl" scale="0.001 0.001 0.001"/>
    </geometry>
    <material name="plastic_matte_gray"/>
  </visual>
  <collision>
    <origin xyz="0 0 0" rpy="0 0 0"/>
    <geometry>
      <mesh filename="package://jumping_spider_description/meshes/base_link.stl" scale="0.001 0.001 0.001"/>
    </geometry>
  </collision>
</link>

<link name="right_pitch_link_1">
  <inertial>
    <origin xyz="0.016410567427321165 0.014000339967106118 -2.5495631168770405e-08" rpy="0 0 0"/>
    <mass value="0.05364753577627055"/>
    <inertia ixx="3.4e-05" iyy="2.8e-05" izz="2.8e-05" ixy="-0.0" iyz="-0.0" ixz="-0.0"/>
  </inertial>
  <visual>
    <origin xyz="-0.619408 0.244258 0.01725" rpy="0 0 0"/>
    <geometry>
      <mesh filename="package://jumping_spider_description/meshes/right_pitch_link_1.stl" scale="0.001 0.001 0.001"/>
    </geometry>
    <material name="rubber_soft"/>
  </visual>
  <collision>
    <origin xyz="-0.619408 0.244258 0.01725" rpy="0 0 0"/>
    <geometry>
      <mesh filename="package://jumping_spider_description/meshes/right_pitch_link_1.stl" scale="0.001 0.001 0.001"/>
    </geometry>
  </collision>
</link>

<link name="right_yaw_link_1">
  <inertial>
    <origin xyz="-1.8147937996815244e-07 4.486868543929212e-07 -0.018999953998501993" rpy="0 0 0"/>
    <mass value="0.004471057524111937"/>
    <inertia ixx="1e-06" iyy="1e-06" izz="1e-06" ixy="-0.0" iyz="-0.0" ixz="0.0"/>
  </inertial>
  <visual>
    <origin xyz="-0.619408 0.230008 -0.00175" rpy="0 0 0"/>
    <geometry>
      <mesh filename="package://jumping_spider_description/meshes/right_yaw_link_1.stl" scale="0.001 0.001 0.001"/>
    </geometry>
    <material name="nylon_12_with_formlabs_fuse_1_3d_printer"/>
  </visual>
  <collision>
    <origin xyz="-0.619408 0.230008 -0.00175" rpy="0 0 0"/>
    <geometry>
      <mesh filename="package://jumping_spider_description/meshes/right_yaw_link_1.stl" scale="0.001 0.001 0.001"/>
    </geometry>
  </collision>
</link>

<link name="left_pitch_link_1">
  <inertial>
    <origin xyz="0.016410818993840115 -0.013999913153812188 -2.8597125140139568e-08" rpy="0 0 0"/>
    <mass value="0.05364753577760987"/>
    <inertia ixx="3.4e-05" iyy="2.8e-05" izz="2.8e-05" ixy="-0.0" iyz="-0.0" ixz="-0.0"/>
  </inertial>
  <visual>
    <origin xyz="-0.619406 -0.244258 0.01725" rpy="0 0 0"/>
    <geometry>
      <mesh filename="package://jumping_spider_description/meshes/left_pitch_link_1.stl" scale="0.001 0.001 0.001"/>
    </geometry>
    <material name="aluminum_satin"/>
  </visual>
  <collision>
    <origin xyz="-0.619406 -0.244258 0.01725" rpy="0 0 0"/>
    <geometry>
      <mesh filename="package://jumping_spider_description/meshes/left_pitch_link_1.stl" scale="0.001 0.001 0.001"/>
    </geometry>
  </collision>
</link>

<link name="left_yaw_link_1">
  <inertial>
    <origin xyz="7.206068308729385e-08 -5.067518613066646e-08 -0.01900003357386317" rpy="0 0 0"/>
    <mass value="0.004471057498872265"/>
    <inertia ixx="1e-06" iyy="1e-06" izz="1e-06" ixy="0.0" iyz="-0.0" ixz="-0.0"/>
  </inertial>
  <visual>
    <origin xyz="-0.619406 -0.230008 -0.00175" rpy="0 0 0"/>
    <geometry>
      <mesh filename="package://jumping_spider_description/meshes/left_yaw_link_1.stl" scale="0.001 0.001 0.001"/>
    </geometry>
    <material name="nylon_12_with_formlabs_fuse_1_3d_printer"/>
  </visual>
  <collision>
    <origin xyz="-0.619406 -0.230008 -0.00175" rpy="0 0 0"/>
    <geometry>
      <mesh filename="package://jumping_spider_description/meshes/left_yaw_link_1.stl" scale="0.001 0.001 0.001"/>
    </geometry>
  </collision>
</link>

<link name="leg_1">
  <inertial>
    <origin xyz="0.03050670749266693 -0.019706984559876968 -0.15348194565318946" rpy="0 0 0"/>
    <mass value="0.11455029789632215"/>
    <inertia ixx="0.003658" iyy="0.003675" izz="3.8e-05" ixy="-0.0" iyz="3e-06" ixz="0.000255"/>
  </inertial>
  <visual>
    <origin xyz="-0.546 -0.02076 0.08025" rpy="0 0 0"/>
    <geometry>
      <mesh filename="package://jumping_spider_description/meshes/leg_1.stl" scale="0.001 0.001 0.001"/>
    </geometry>
    <material name="aluminum_satin"/>
  </visual>
  <collision>
    <origin xyz="-0.546 -0.02076 0.08025" rpy="0 0 0"/>
    <geometry>
      <mesh filename="package://jumping_spider_description/meshes/leg_1.stl" scale="0.001 0.001 0.001"/>
    </geometry>
  </collision>
</link>

<link name="rotor_0_1">
  <inertial>
    <origin xyz="3.0654330738233426e-05 1.0845872533415957e-09 -0.0004453815192420191" rpy="0 0 0"/>
    <mass value="0.019049234818759395"/>
    <inertia ixx="4e-06" iyy="0.000175" izz="0.000176" ixy="-6e-06" iyz="-0.0" ixz="-1.2e-05"/>
  </inertial>
  <visual>
    <origin xyz="-0.295991 0.4 -0.025825" rpy="0 0 0"/>
    <geometry>
      <mesh filename="package://jumping_spider_description/meshes/rotor_0_1.stl" scale="0.001 0.001 0.001"/>
    </geometry>
    <material name="carbon_fiber_twill"/>
  </visual>
  <collision>
    <origin xyz="-0.295991 0.4 -0.025825" rpy="0 0 0"/>
    <geometry>
      <mesh filename="package://jumping_spider_description/meshes/rotor_0_1.stl" scale="0.001 0.001 0.001"/>
    </geometry>
  </collision>
</link>

<link name="rotor_1_1">
  <inertial>
    <origin xyz="-3.8194494143051205e-05 -8.094279331238852e-06 -0.0004447218404259358" rpy="0 0 0"/>
    <mass value="0.01904923481875957"/>
    <inertia ixx="0.000173" iyy="4e-06" izz="0.000177" ixy="1.8e-05" iyz="2e-06" ixz="-0.0"/>
  </inertial>
  <visual>
    <origin xyz="0.295991 -0.4 -0.025825" rpy="0 0 0"/>
    <geometry>
      <mesh filename="package://jumping_spider_description/meshes/rotor_1_1.stl" scale="0.001 0.001 0.001"/>
    </geometry>
    <material name="carbon_fiber_twill"/>
  </visual>
  <collision>
    <origin xyz="0.295991 -0.4 -0.025825" rpy="0 0 0"/>
    <geometry>
      <mesh filename="package://jumping_spider_description/meshes/rotor_1_1.stl" scale="0.001 0.001 0.001"/>
    </geometry>
  </collision>
</link>

<link name="rotor_2_1">
  <inertial>
    <origin xyz="3.066465282558495e-05 1.1027025303977922e-07 -0.0004453815209966294" rpy="0 0 0"/>
    <mass value="0.01904923107573158"/>
    <inertia ixx="4e-06" iyy="0.000175" izz="0.000176" ixy="8e-06" iyz="1e-06" ixz="-1.2e-05"/>
  </inertial>
  <visual>
    <origin xyz="-0.295991 -0.4 -0.025825" rpy="0 0 0"/>
    <geometry>
      <mesh filename="package://jumping_spider_description/meshes/rotor_2_1.stl" scale="0.001 0.001 0.001"/>
    </geometry>
    <material name="carbon_fiber_twill"/>
  </visual>
  <collision>
    <origin xyz="-0.295991 -0.4 -0.025825" rpy="0 0 0"/>
    <geometry>
      <mesh filename="package://jumping_spider_description/meshes/rotor_2_1.stl" scale="0.001 0.001 0.001"/>
    </geometry>
  </collision>
</link>

<link name="rotor_3_1">
  <inertial>
    <origin xyz="-3.789662196262977e-05 8.066042666232676e-06 -0.0004447486788024084" rpy="0 0 0"/>
    <mass value="0.019049231075731584"/>
    <inertia ixx="0.000172" iyy="6e-06" izz="0.000177" ixy="-2.4e-05" iyz="-1e-06" ixz="-0.0"/>
  </inertial>
  <visual>
    <origin xyz="0.295991 0.4 -0.025825" rpy="0 0 0"/>
    <geometry>
      <mesh filename="package://jumping_spider_description/meshes/rotor_3_1.stl" scale="0.001 0.001 0.001"/>
    </geometry>
    <material name="carbon_fiber_twill"/>
  </visual>
  <collision>
    <origin xyz="0.295991 0.4 -0.025825" rpy="0 0 0"/>
    <geometry>
      <mesh filename="package://jumping_spider_description/meshes/rotor_3_1.stl" scale="0.001 0.001 0.001"/>
    </geometry>
  </collision>
</link>

<link name="right_arm_1">
  <inertial>
    <origin xyz="-0.0033576494463016804 -0.07598106811746876 -0.024740625208792708" rpy="0 0 0"/>
    <mass value="0.08923704603024427"/>
    <inertia ixx="0.000421" iyy="0.000131" izz="0.000476" ixy="9.9e-05" iyz="-0.0" ixz="-0.0"/>
  </inertial>
  <visual>
    <origin xyz="-0.575 0.035 -0.006" rpy="0 0 0"/>
    <geometry>
      <mesh filename="package://jumping_spider_description/meshes/right_arm_1.stl" scale="0.001 0.001 0.001"/>
    </geometry>
    <material name="bamboo_light_semigloss"/>
  </visual>
  <collision>
    <origin xyz="-0.575 0.035 -0.006" rpy="0 0 0"/>
    <geometry>
      <mesh filename="package://jumping_spider_description/meshes/right_arm_1.stl" scale="0.001 0.001 0.001"/>
    </geometry>
  </collision>
</link>

<link name="left_arm_1">
  <inertial>
    <origin xyz="-0.003358315058306194 0.07598103762896487 -0.024759352708196423" rpy="0 0 0"/>
    <mass value="0.08923702592897251"/>
    <inertia ixx="0.000421" iyy="0.000131" izz="0.000476" ixy="-9.9e-05" iyz="-0.0" ixz="0.0"/>
  </inertial>
  <visual>
    <origin xyz="-0.575 -0.035 -0.006" rpy="0 0 0"/>
    <geometry>
      <mesh filename="package://jumping_spider_description/meshes/left_arm_1.stl" scale="0.001 0.001 0.001"/>
    </geometry>
    <material name="steel_satin"/>
  </visual>
  <collision>
    <origin xyz="-0.575 -0.035 -0.006" rpy="0 0 0"/>
    <geometry>
      <mesh filename="package://jumping_spider_description/meshes/left_arm_1.stl" scale="0.001 0.001 0.001"/>
    </geometry>
  </collision>
</link>

<link name="gimbal_pitch_1">
  <inertial>
    <origin xyz="-0.0011807057318703323 0.02990155922168788 0.017311002256869518" rpy="0 0 0"/>
    <mass value="0.03189073176342107"/>
    <inertia ixx="1.6e-05" iyy="1.5e-05" izz="1.2e-05" ixy="1e-06" iyz="3e-06" ixz="-2e-06"/>
  </inertial>
  <visual>
    <origin xyz="-0.11 0.0285 -0.237685" rpy="0 0 0"/>
    <geometry>
      <mesh filename="package://jumping_spider_description/meshes/gimbal_pitch_1.stl" scale="0.001 0.001 0.001"/>
    </geometry>
    <material name="opaque252525"/>
  </visual>
  <collision>
    <origin xyz="-0.11 0.0285 -0.237685" rpy="0 0 0"/>
    <geometry>
      <mesh filename="package://jumping_spider_description/meshes/gimbal_pitch_1.stl" scale="0.001 0.001 0.001"/>
    </geometry>
  </collision>
</link>

<link name="gimbal_roll_1">
  <inertial>
    <origin xyz="0.02565588384486469 -0.003957377189178218 -0.0005037933925707005" rpy="0 0 0"/>
    <mass value="0.017714817282487673"/>
    <inertia ixx="6e-06" iyy="7e-06" izz="1.2e-05" ixy="-1e-06" iyz="0.0" ixz="-0.0"/>
  </inertial>
  <visual>
    <origin xyz="-0.0325 0.0 -0.237535" rpy="0 0 0"/>
    <geometry>
      <mesh filename="package://jumping_spider_description/meshes/gimbal_roll_1.stl" scale="0.001 0.001 0.001"/>
    </geometry>
    <material name="nylon_12_with_formlabs_fuse_1_3d_printer"/>
  </visual>
  <collision>
    <origin xyz="-0.0325 0.0 -0.237535" rpy="0 0 0"/>
    <geometry>
      <mesh filename="package://jumping_spider_description/meshes/gimbal_roll_1.stl" scale="0.001 0.001 0.001"/>
    </geometry>
  </collision>
</link>

<joint name="right_pitch_joint" type="continuous">
  <origin xyz="0.0 -0.01425 -0.019" rpy="0 0 0"/>
  <parent link="right_yaw_link_1"/>
  <child link="right_pitch_link_1"/>
  <axis xyz="-3e-06 -1.0 -0.0"/>
</joint>

<joint name="right_yaw_joint" type="continuous">
  <origin xyz="0.044408 -0.195008 -0.00425" rpy="0 0 0"/>
  <parent link="right_arm_1"/>
  <child link="right_yaw_link_1"/>
  <axis xyz="-0.0 0.0 -1.0"/>
</joint>

<joint name="left_pitch_joint" type="continuous">
  <origin xyz="0.0 0.01425 -0.019" rpy="0 0 0"/>
  <parent link="left_yaw_link_1"/>
  <child link="left_pitch_link_1"/>
  <axis xyz="1.2e-05 -1.0 0.0"/>
</joint>

<joint name="left_yaw_joint" type="continuous">
  <origin xyz="0.044406 0.195008 -0.00425" rpy="0 0 0"/>
  <parent link="left_arm_1"/>
  <child link="left_yaw_link_1"/>
  <axis xyz="0.0 -0.0 -1.0"/>
</joint>

<joint name="leg_1_joint" type="continuous">
  <origin xyz="0.546 0.02076 -0.08025" rpy="0 0 0"/>
  <parent link="base_link"/>
  <child link="leg_1"/>
  <axis xyz="-0.0 -1.0 -0.0"/>
</joint>

<joint name="rotor_0_1_joint" type="continuous">
  <origin xyz="0.295991 -0.4 0.025825" rpy="0 0 0"/>
  <parent link="base_link"/>
  <child link="rotor_0_1"/>
  <axis xyz="-0.087156 0.0 0.996195"/>
</joint>

<joint name="rotor_1_1_joint" type="continuous">
  <origin xyz="-0.295991 0.4 0.025825" rpy="0 0 0"/>
  <parent link="base_link"/>
  <child link="rotor_1_1"/>
  <axis xyz="0.087156 0.0 0.996195"/>
</joint>

<joint name="rotor_2_1_joint" type="continuous">
  <origin xyz="0.295991 0.4 0.025825" rpy="0 0 0"/>
  <parent link="base_link"/>
  <child link="rotor_2_1"/>
  <axis xyz="-0.087156 -0.0 0.996195"/>
</joint>

<joint name="rotor_3_1_joint" type="continuous">
  <origin xyz="-0.295991 -0.4 0.025825" rpy="0 0 0"/>
  <parent link="base_link"/>
  <child link="rotor_3_1"/>
  <axis xyz="0.087156 0.0 0.996195"/>
</joint>

<joint name="right_arm_joint" type="continuous">
  <origin xyz="0.575 -0.035 0.006" rpy="0 0 0"/>
  <parent link="base_link"/>
  <child link="right_arm_1"/>
  <axis xyz="-0.0 0.0 1.0"/>
</joint>

<joint name="left_arm_joint" type="continuous">
  <origin xyz="0.575 0.035 0.006" rpy="0 0 0"/>
  <parent link="base_link"/>
  <child link="left_arm_1"/>
  <axis xyz="-0.0 0.0 1.0"/>
</joint>

<joint name="gimbal_pitch_joint" type="continuous">
  <origin xyz="0.0775 -0.0285 0.00015" rpy="0 0 0"/>
  <parent link="gimbal_roll_1"/>
  <child link="gimbal_pitch_1"/>
  <axis xyz="-0.0 -1.0 -0.0"/>
</joint>

<joint name="gimbal_roll_joint" type="continuous">
  <origin xyz="0.0325 0.0 0.237535" rpy="0 0 0"/>
  <parent link="base_link"/>
  <child link="gimbal_roll_1"/>
  <axis xyz="-1.0 0.0 -0.0"/>
</joint>

</robot>
