<?xml version='1.0'?>
<sdf version='1.9'>
  <model name='suction_anchor'>
        <link name="shoulder_link">
        <inertial>
            <mass>0.001</mass>
            <inertia>
                <ixx>0.0001</ixx>
                <ixy>0</ixy>
                <ixz>0</ixz>
                <iyy>0.0001</iyy>
                <iyz>0</iyz>
                <izz>0.0001</izz>
            </inertia>
        </inertial>
        <visual name='visual'>
            <geometry>
                <box>
                    <size>0.025 0.025 0.025</size>
                </box>
            </geometry>
            <material>
                <ambient>0.0 1 0.0 1</ambient>
                <diffuse>0.0 1 0.0 1</diffuse>
                <specular>0.0 1 0.0 1</specular>
            </material>
        </visual>
    </link>
        <link name="upper_arm">
        <pose relative_to="shoulder_link">.0125 0 0 0 0 0</pose>
        <inertial>
            <mass>0.001</mass>
            <inertia>
                <ixx>0.0001</ixx>
                <ixy>0</ixy>
                <ixz>0</ixz>
                <iyy>0.0001</iyy>
                <iyz>0</iyz>
                <izz>0.0001</izz>
            </inertia>
        </inertial>
        <visual name='visual'>
            <geometry>
                <box>
                    <size>0.2 0.025 0.05</size>
                </box>
            </geometry>
            <material>
                <ambient>0.0 1 0.0 1</ambient>
                <diffuse>0.0 1 0.0 1</diffuse>
                <specular>0.0 1 0.0 1</specular>
            </material>
        </visual>
    </link>
    <link name="forearm">
    <pose relative_to="upper_arm">0.2 0 0 0 0 0</pose>
        <inertial>
            <mass>0.001</mass>
            <inertia>
                <ixx>0.0001</ixx>
                <ixy>0</ixy>
                <ixz>0</ixz>
                <iyy>0.0001</iyy>
                <iyz>0</iyz>
                <izz>0.0001</izz>
            </inertia>
        </inertial>
        <visual name='visual'>
            <geometry>
                <box>
                    <size>0.2 0.025 0.05</size>
                </box>
            </geometry>
            <material>
                <ambient>0.0 1 0.0 1</ambient>
                <diffuse>0.0 1 0.0 1</diffuse>
                <specular>0.0 1 0.0 1</specular>
            </material>
        </visual>
    </link>
    <link name='probe'>
    <pose relative_to="forearm">0.1 0 0 0 0 0</pose> <!--angles are in radian-->
        <inertial>
            <mass>0.001</mass>
            <inertia>
                <ixx>0.0001</ixx>
                <ixy>0</ixy>
                <ixz>0</ixz>
                <iyy>0.0001</iyy>
                <iyz>0</iyz>
                <izz>0.0001</izz>
            </inertia>
        </inertial>
        <visual name='visual'>
            <geometry>
                <box>
                    <size>0.05 0.1 0.1</size>
                </box>
            </geometry>
            <material>
                <ambient>0.0 1 0.0 1</ambient>
                <diffuse>0.0 1 0.0 1</diffuse>
                <specular>0.0 1 0.0 1</specular>
            </material>
        </visual>
        <collision name='collision'>
            <geometry>
                <box>
                    <size>0.05 0.1 0.1</size>
                </box>
            </geometry>
            <surface>
                <friction>
                    <ode>
                        <mu>
                            50.0
                        </mu>
                        <mu2>
                            50.0
                        </mu2>
                    </ode>
                </friction>
                <contact>
                    <ode>
                    <max_vel>0</max_vel>
                    <min_depth>0.01</min_depth>
                    </ode>
                </contact>
                </surface>
        </collision>
        <sensor name='sensor_contact' type='contact'>
            <contact>
                <collision>collision</collision>
            </contact>
        </sensor>
    </link>
    <joint name='shoulder_joint' type='revolute'>
        <pose relative_to='upper_arm'>-0.1 0 -0.1 0 0 0</pose>
        <parent>shoulder_link</parent>
        <child>upper_arm</child>
        <axis>
            <xyz expressed_in='__model__'>0 1 0</xyz>
            <limit>
                <lower>-1.79769e+308</lower>    <!--negative infinity-->
                <upper>1.79769e+308</upper>     <!--positive infinity-->
            </limit>
            <dynamics>
                <damping>10</damping>
                <spring_reference> .7 </spring_reference>
                <spring_stiffness> 400 </spring_stiffness>
            </dynamics>
        </axis>
    </joint>
    <joint name='elbow_joint' type='revolute'>
        <pose relative_to='forearm'>-.1 0 0 0 0 0</pose>
        <parent>upper_arm</parent>
        <child>forearm</child>
        <axis>
            <xyz expressed_in='__model__'>0 1 0</xyz>
            <limit>
                <lower>-1.79769e+308</lower>    <!--negative infinity-->
                <upper>1.79769e+308</upper>     <!--positive infinity-->
            </limit>
            <dynamics>
                <damping>10</damping>
                <spring_reference> -1.4 </spring_reference>
                <spring_stiffness> 400 </spring_stiffness>
            </dynamics>
        </axis>
    </joint>
    <joint name='wrist_joint' type='revolute'>
        <pose relative_to='probe'>-.025 0 0 0 0 0</pose>
        <parent>forearm</parent>
        <child>probe</child>
        <axis>
            <xyz expressed_in='__model__'>0 1 0</xyz>
            <limit>
                <lower>-1.79769e+308</lower>    <!--negative infinity-->
                <upper>1.79769e+308</upper>     <!--positive infinity-->
            </limit>
            <dynamics>
                <damping>10</damping>
                <spring_reference> .7 </spring_reference>
                <spring_stiffness> 400 </spring_stiffness>
            </dynamics>
        </axis>
    </joint>
  </model>
</sdf>