<?xml version='1.0'?>
<sdf version='1.11'>
  <model name='jumping_spider'>
    <link name='base_link'>
      <inertial>
        <pose>-0.060807735479528308 -0.00050335318105708112 -0.018253570312340289 0 0 0</pose>
        <mass>8.0806211980470266</mass>
        <inertia>
          <ixx>0.331955</ixx>
          <ixy>-0.00072800000000000002</ixy>
          <ixz>0.042735000000000002</ixz>
          <iyy>0.48839500000000002</iyy>
          <iyz>0.000368</iyz>
          <izz>0.70259099999999997</izz>
        </inertia>
      </inertial>
      <sensor name="imu_sensor" type="imu">
        <pose degrees="true">-0.060807735479528308 -0.00050335318105708112 -0.018253570312340289 180 0 0</pose>
        <always_on>1</always_on>
        <update_rate>1000.0</update_rate>
      </sensor>
        <collision name='base_collision_0'>
        <pose>0.3 0.285 -0.145 0 0 0</pose>
        <geometry>
          <box>
            <size>0.03 0.03 0.2</size>
          </box>
        </geometry>
        <surface>
          <contact>
            <ode>
              <max_vel>100.0</max_vel>
              <min_depth>0.001</min_depth>
            </ode>
          </contact>
          <friction>
            <ode>
              <mu>100000.0</mu>
              <mu2>100000.0</mu2>
            </ode>
          </friction>
        </surface>
        </collision>
        <collision name='base_collision_1'>
        <pose>-0.3 0.285 -0.145 0 0 0</pose>
        <geometry>
          <box>
            <size>0.03 0.03 0.2</size>
          </box>
        </geometry>
        <surface>
          <contact>
            <ode>
              <max_vel>100.0</max_vel>
              <min_depth>0.001</min_depth>
            </ode>
          </contact>
          <friction>
            <ode>
              <mu>100000.0</mu>
              <mu2>100000.0</mu2>
            </ode>
          </friction>
        </surface>
        </collision>
        <collision name='base_collision_2'>
        <pose>0.3 -0.285 -0.145 0 0 0</pose>
        <geometry>
          <box>
            <size>0.03 0.03 0.2</size>
          </box>
        </geometry>
        <surface>
          <contact>
            <ode>
              <max_vel>100.0</max_vel>
              <min_depth>0.001</min_depth>
            </ode>
          </contact>
          <friction>
            <ode>
              <mu>100000.0</mu>
              <mu2>100000.0</mu2>
            </ode>
          </friction>
        </surface>
        </collision>
        <collision name='base_collision_3'>
        <pose>-0.3 -0.285 -0.145 0 0 0</pose>
        <geometry>
          <box>
            <size>0.03 0.03 0.2</size>
          </box>
        </geometry>
        <surface>
          <contact>
            <ode>
              <max_vel>100.0</max_vel>
              <min_depth>0.001</min_depth>
            </ode>
          </contact>
          <friction>
            <ode>
              <mu>100000.0</mu>
              <mu2>100000.0</mu2>
            </ode>
          </friction>
        </surface>
        </collision>
        <visual name='base_link_visual'>
        <pose>0 0 0 0 0 0</pose>
        <geometry>
          <mesh>
            <scale>0.001 0.001 0.001</scale>
            <uri>model://jumping_spider/meshes/base_link.stl</uri>
          </mesh>
        </geometry>
        <material>
          <diffuse>0 1 0 1</diffuse>
          <ambient>0 0 0 1</ambient>
        </material>
      </visual>
    </link>
    <joint name='leg_1_joint' type='revolute'>
      <pose relative_to='base_link'>0.54600000000000004 0.020760000000000001 -0.080250000000000002 0 1.5 0</pose>
      <parent>base_link</parent>
      <child>leg_1</child>
      <axis>
        <xyz>0 -1 0</xyz>
        <limit>
          <lower>-inf</lower>
          <upper>inf</upper>
        </limit>
        <dynamics>
          <!-- <spring_reference>0</spring_reference>
          <spring_stiffness>0</spring_stiffness> -->
          <damping>1</damping>
        </dynamics>
      </axis>
    </joint>
    <link name='leg_1'>
      <pose relative_to='leg_1_joint'>0 0 0 0 0 0</pose>
      <inertial>
        <pose>0.030506707492666929 -0.019706984559876971 -0.15348194565318951 0 0 0</pose>
        <mass>0.11455029789632221</mass>
        <inertia>
          <ixx>0.0036579999999999998</ixx>
          <ixy>0</ixy>
          <ixz>0.00025500000000000002</ixz>
          <iyy>0.0036749999999999999</iyy>
          <iyz>3.0000000000000001e-06</iyz>
          <izz>3.8000000000000002e-05</izz>
        </inertia>
      </inertial>
      <collision name='leg_collision'>
        <pose>0.062 0 -0.47 0 0 0</pose>
        <geometry>
          <box>
            <size>0.01 0.05 0.05</size>
          </box>
        </geometry>
        <surface>
          <contact>
            <ode>
              <max_vel>100.0</max_vel>
              <min_depth>0.001</min_depth>
            </ode>
          </contact>
          <friction>
            <ode>
              <mu>100000.0</mu>
              <mu2>100000.0</mu2>
            </ode>
          </friction>
        </surface>
        </collision>
      <visual name='leg_1_visual'>
        <pose>-0.54600000000000004 -0.020760000000000001 0.080250000000000002 0 0 0</pose>
        <geometry>
          <mesh>
            <scale>0.001 0.001 0.001</scale>
            <uri>model://jumping_spider/meshes/leg_1.stl</uri>
          </mesh>
        </geometry>
        <material>
          <diffuse>0 0 0 1</diffuse>
          <ambient>0 0 0 1</ambient>
        </material>
      </visual>
    </link>
    <joint name='rotor_0_1_joint' type='revolute'>
      <pose relative_to='base_link'>0.295991 -0.40000000000000002 0.025825000000000001 0 0 0</pose>
      <parent>base_link</parent>
      <child>rotor_0_1</child>
      <axis>
        <xyz>-0.087155999999999997 0 0.99619500000000005</xyz>
        <limit>
          <lower>-inf</lower>
          <upper>inf</upper>
        </limit>
        <dynamics>
          <damping>0.004</damping>
        </dynamics>
      </axis>
    </joint>
    <link name='rotor_0_1'>
      <pose relative_to='rotor_0_1_joint'>0 0 0 0 0 0</pose>
      <inertial>
        <pose>3.0654330738233433e-05 1.0845872533415961e-09 -0.00044538151924201907 0 0 0</pose>
        <mass>0.019049234818759399</mass>
        <inertia>
          <ixx>3.9999999999999998e-06</ixx>
          <ixy>-6.0000000000000002e-06</ixy>
          <ixz>-1.2e-05</ixz>
          <iyy>0.000175</iyy>
          <iyz>0</iyz>
          <izz>0.000176</izz>
        </inertia>
      </inertial>
       <collision name='rotor_0_1_collision'>
        <pose>0 0 0 0 0 0</pose>
            <geometry>
                <cylinder>
                    <length>0.035</length>
                    <radius>0.23</radius>
                </cylinder>
            </geometry>
            <surface>
                <friction>
                    <ode>
                        <mu>
                            50.0
                        </mu>
                        <mu2>
                            50.0
                        </mu2>
                    </ode>
                </friction>
                <contact>
                    <ode>
                    <max_vel>0</max_vel>
                    <min_depth>0.001</min_depth>
                    </ode>
                </contact>
                </surface>
        </collision>
        <visual name='rotor_0_1_visual'>
        <pose>-0.295991 0.40000000000000002 -0.025825000000000001 0 0 0</pose>
        <geometry>
          <mesh>
            <scale>0.001 0.001 0.001</scale>
            <uri>model://jumping_spider/meshes/rotor_0_1.stl</uri>
          </mesh>
        </geometry>
        <material>
          <diffuse>0 0 0 1</diffuse>
          <ambient>0 0 0 1</ambient>
        </material>
      </visual>
    </link>
    <joint name='rotor_1_1_joint' type='revolute'>
      <pose relative_to='base_link'>-0.295991 0.40000000000000002 0.025825000000000001 0 0 0</pose>
      <parent>base_link</parent>
      <child>rotor_1_1</child>
      <axis>
        <xyz>0.087155999999999997 0 0.99619500000000005</xyz>
        <limit>
          <lower>-inf</lower>
          <upper>inf</upper>
        </limit>
        <dynamics>
          <damping>0.004</damping>
        </dynamics>
      </axis>
    </joint>
    <link name='rotor_1_1'>
      <pose relative_to='rotor_1_1_joint'>0 0 0 0 0 0</pose>
      <inertial>
        <pose>-3.8194494143051212e-05 -8.0942793312388517e-06 -0.00044472184042593579 0 0 0</pose>
        <mass>0.019049234818759569</mass>
        <inertia>
          <ixx>1.732e-4</ixx>
          <ixy>1.763e-5</ixy>
          <ixz>1.854e-8</ixz>
          <iyy>4.325e-6</iyy>
          <iyz>1.623e-6</iyz>
          <izz>1.767e-4</izz>
        </inertia>
      </inertial>
      <collision name='rotor_1_1_collision'>
        <pose>0 0 0 0 0 0</pose>
            <geometry>
                <cylinder>
                    <length>0.035</length>
                    <radius>0.23</radius>
                </cylinder>
            </geometry>
            <surface>
                <friction>
                    <ode>
                        <mu>
                            50.0
                        </mu>
                        <mu2>
                            50.0
                        </mu2>
                    </ode>
                </friction>
                <contact>
                    <ode>
                    <max_vel>0</max_vel>
                    <min_depth>0.001</min_depth>
                    </ode>
                </contact>
                </surface>
        </collision>
            <visual name='rotor_1_1_visual'>
        <pose>0.295991 -0.40000000000000002 -0.025825000000000001 0 0 0</pose>
        <geometry>
          <mesh>
            <scale>0.001 0.001 0.001</scale>
            <uri>model://jumping_spider/meshes/rotor_1_1.stl</uri>
          </mesh>
        </geometry>
        <material>
          <diffuse>0 0 0 1</diffuse>
          <ambient>0 0 0 1</ambient>
        </material>
      </visual>
    </link>
    <joint name='rotor_2_1_joint' type='revolute'>
      <pose relative_to='base_link'>0.295991 0.40000000000000002 0.025825000000000001 0 0 0</pose>
      <parent>base_link</parent>
      <child>rotor_2_1</child>
      <axis>
        <xyz>-0.087155999999999997 0 0.99619500000000005</xyz>
        <limit>
          <lower>-inf</lower>
          <upper>inf</upper>
        </limit>
        <dynamics>
          <damping>0.004</damping>
        </dynamics>
      </axis>
    </joint>
    <link name='rotor_2_1'>
      <pose relative_to='rotor_2_1_joint'>0 0 0 0 0 0</pose>
      <inertial>
        <pose>3.0664652825584948e-05 1.1027025303977919e-07 -0.00044538152099662942 0 0 0</pose>
        <mass>0.019049231075731581</mass>
        <inertia>
          <ixx>3.9999999999999998e-06</ixx>
          <ixy>7.9999999999999996e-06</ixy>
          <ixz>-1.2e-05</ixz>
          <iyy>0.000175</iyy>
          <iyz>9.9999999999999995e-07</iyz>
          <izz>0.000176</izz>
        </inertia>
      </inertial>
      <collision name='rotor_2_1_collision'>
        <pose>0 0 0 0 0 0</pose>
            <geometry>
                <cylinder>
                    <length>0.035</length>
                    <radius>0.23</radius>
                </cylinder>
            </geometry>
            <surface>
                <friction>
                    <ode>
                        <mu>
                            50.0
                        </mu>
                        <mu2>
                            50.0
                        </mu2>
                    </ode>
                </friction>
                <contact>
                    <ode>
                    <max_vel>0</max_vel>
                    <min_depth>0.001</min_depth>
                    </ode>
                </contact>
                </surface>
        </collision>
            <visual name='rotor_2_1_visual'>
        <pose>-0.295991 -0.40000000000000002 -0.025825000000000001 0 0 0</pose>
        <geometry>
          <mesh>
            <scale>0.001 0.001 0.001</scale>
            <uri>model://jumping_spider/meshes/rotor_2_1.stl</uri>
          </mesh>
        </geometry>
        <material>
          <diffuse>0 0 0 1</diffuse>
          <ambient>0 0 0 1</ambient>
        </material>
      </visual>
    </link>
    <joint name='rotor_3_1_joint' type='revolute'>
      <pose relative_to='base_link'>-0.295991 -0.40000000000000002 0.025825000000000001 0 0 0</pose>
      <parent>base_link</parent>
      <child>rotor_3_1</child>
      <axis>
        <xyz>0.087155999999999997 0 0.99619500000000005</xyz>
        <limit>
          <lower>-inf</lower>
          <upper>inf</upper>
        </limit>
        <dynamics>
          <damping>0.004</damping>
        </dynamics>
      </axis>
    </joint>
    <link name='rotor_3_1'>
      <pose relative_to='rotor_3_1_joint'>0 0 0 0 0 0</pose>
      <inertial>
        <pose>-3.7896621962629773e-05 8.0660426662326756e-06 -0.0004447486788024084 0 0 0</pose>
        <mass>0.019049231075731581</mass>
        <inertia>
          <ixx>0.00017200000000000001</ixx>
          <ixy>-2.4000000000000001e-05</ixy>
          <ixz>0</ixz>
          <iyy>6.0000000000000002e-06</iyy>
          <iyz>-9.9999999999999995e-07</iyz>
          <izz>0.00017699999999999999</izz>
        </inertia>
      </inertial>
      <collision name='rotor_3_1_collision'>
        <pose>0 0 0 0 0 0</pose>
            <geometry>
                <cylinder>
                    <length>0.035</length>
                    <radius>0.23</radius>
                </cylinder>
            </geometry>
            <surface>
                <friction>
                    <ode>
                        <mu>
                            50.0
                        </mu>
                        <mu2>
                            50.0
                        </mu2>
                    </ode>
                </friction>
                <contact>
                    <ode>
                    <max_vel>0</max_vel>
                    <min_depth>0.001</min_depth>
                    </ode>
                </contact>
                </surface>
        </collision>
            <visual name='rotor_3_1_visual'>
        <pose>0.295991 0.40000000000000002 -0.025825000000000001 0 0 0</pose>
        <geometry>
          <mesh>
            <scale>0.001 0.001 0.001</scale>
            <uri>model://jumping_spider/meshes/rotor_3_1.stl</uri>
          </mesh>
        </geometry>
        <material>
          <diffuse>0 0 0 1</diffuse>
          <ambient>0 0 0 1</ambient>
        </material>
      </visual>
    </link>
    <joint name='right_arm_joint' type='revolute'>
      <pose relative_to='base_link'>0.57499999999999996 -0.035000000000000003 0.0060000000000000001 0 0 0</pose>
      <parent>base_link</parent>
      <child>right_arm_1</child>
      <axis>
        <xyz>0 0 1</xyz>
        <limit>
          <lower>-inf</lower>
          <upper>inf</upper>
        </limit>
        <dynamics>
          <spring_reference>0</spring_reference>
          <spring_stiffness>20</spring_stiffness>
<damping>1</damping>
        </dynamics>
      </axis>
    </joint>
    <link name='right_arm_1'>
      <pose relative_to='right_arm_joint'>0 0 0 0 0 0</pose>
      <inertial>
        <pose>-0.00335764944630168 -0.075981068117468756 -0.024740625208792711 0 0 0</pose>
        <mass>0.089237046030244266</mass>
        <inertia>
          <ixx>0.00042099999999999999</ixx>
          <ixy>9.8999999999999994e-05</ixy>
          <ixz>0</ixz>
          <iyy>0.00013100000000000001</iyy>
          <iyz>0</iyz>
          <izz>0.00047600000000000002</izz>
        </inertia>
      </inertial>
            <visual name='right_arm_1_visual'>
        <pose>-0.57499999999999996 0.035000000000000003 -0.0060000000000000001 0 0 0</pose>
        <geometry>
          <mesh>
            <scale>0.001 0.001 0.001</scale>
            <uri>model://jumping_spider/meshes/right_arm_1.stl</uri>
          </mesh>
        </geometry>
        <material>
          <diffuse>0 0 0 1</diffuse>
          <ambient>0 0 0 1</ambient>
        </material>
      </visual>
    </link>
    <joint name='right_yaw_joint' type='revolute'>
      <pose relative_to='right_arm_1'>0.044408000000000003 -0.19500799999999999 -0.0042500000000000003 0 0 0</pose>
      <parent>right_arm_1</parent>
      <child>right_yaw_link_1</child>
      <axis>
        <xyz>0 0 -1</xyz>
        <limit>
          <lower>-inf</lower>
          <upper>inf</upper>
        </limit>
        <dynamics>
          <spring_reference>0</spring_reference>
          <spring_stiffness>20</spring_stiffness>
<damping>1</damping>
        </dynamics>
      </axis>
    </joint>
    <link name='right_yaw_link_1'>
      <pose relative_to='right_yaw_joint'>0 0 0 0 0 0</pose>
      <inertial>
        <pose>-1.8147937996815239e-07 4.4868685439292122e-07 -0.018999953998501989 0 0 0</pose>
        <mass>0.0044710575241119366</mass>
        <inertia>
          <ixx>9.9999999999999995e-07</ixx>
          <ixy>0</ixy>
          <ixz>0</ixz>
          <iyy>9.9999999999999995e-07</iyy>
          <iyz>0</iyz>
          <izz>9.9999999999999995e-07</izz>
        </inertia>
      </inertial>
            <visual name='right_yaw_link_1_visual'>
        <pose>-0.61940799999999996 0.23000799999999999 -0.00175 0 0 0</pose>
        <geometry>
          <mesh>
            <scale>0.001 0.001 0.001</scale>
            <uri>model://jumping_spider/meshes/right_yaw_link_1.stl</uri>
          </mesh>
        </geometry>
        <material>
          <diffuse>0 0 1 1</diffuse>
          <ambient>0 0 0 1</ambient>
        </material>
      </visual>
    </link>
    <joint name='right_pitch_joint' type='revolute'>
      <pose relative_to='right_yaw_link_1'>0 -0.014250000000000001 -0.019 0 0 0</pose>
      <parent>right_yaw_link_1</parent>
      <child>right_pitch_link_1</child>
      <axis>
        <xyz>-3.0000000000000001e-06 -1 0</xyz>
        <limit>
          <lower>-inf</lower>
          <upper>inf</upper>
        </limit>
        <dynamics>
          <spring_reference>0</spring_reference>
          <spring_stiffness>20</spring_stiffness>
<damping>1</damping>
        </dynamics>
      </axis>
    </joint>
    <link name='right_pitch_link_1'>
      <pose relative_to='right_pitch_joint'>0 0 0 0 0 0</pose>
      <inertial>
        <pose>0.016410567427321169 0.01400033996710612 -2.5495631168770408e-08 0 0 0</pose>
        <mass>0.053647535776270551</mass>
        <inertia>
          <ixx>3.4e-05</ixx>
          <ixy>0</ixy>
          <ixz>0</ixz>
          <iyy>2.8e-05</iyy>
          <iyz>0</iyz>
          <izz>2.8e-05</izz>
        </inertia>
      </inertial>
      <collision name='right_suction_collision'>
        <pose>0.03 0.01 0 0 1.570795 0</pose>
            <geometry>
                <cylinder>
                    <length>0.01</length>
                    <radius>0.0455</radius>
                </cylinder>
            </geometry>
            <surface>
                <friction>
                    <ode>
                        <mu>
                            50.0
                        </mu>
                        <mu2>
                            50.0
                        </mu2>
                    </ode>
                </friction>
                <contact>
                    <ode>
                    <max_vel>0</max_vel>
                    <min_depth>0.001</min_depth>
                    </ode>
                </contact>
                </surface>
        </collision>
        <sensor name='sensor_contact' type='contact'>
            <contact>
                <collision>right_suction_collision</collision>
            </contact>
        </sensor>
        <visual name='right_pitch_link_1_visual'>
        <pose>-0.61940799999999996 0.244258 0.017250000000000001 0 0 0</pose>
        <geometry>
          <mesh>
            <scale>0.001 0.001 0.001</scale>
            <uri>model://jumping_spider/meshes/right_pitch_link_1.stl</uri>
          </mesh>
        </geometry>
        <material>
          <diffuse>1 0 0 1</diffuse>
          <ambient>0 0 0 1</ambient>
        </material>
      </visual>
    </link>
    <joint name='left_arm_joint' type='revolute'>
      <pose relative_to='base_link'>0.57499999999999996 0.035000000000000003 0.0060000000000000001 0 0 0</pose>
      <parent>base_link</parent>
      <child>left_arm_1</child>
      <axis>
        <xyz>0 0 1</xyz>
        <limit>
          <lower>-inf</lower>
          <upper>inf</upper>
        </limit>
        <dynamics>
          <spring_reference>0</spring_reference>
          <spring_stiffness>20</spring_stiffness>
<damping>1</damping>
        </dynamics>
      </axis>
    </joint>
    <link name='left_arm_1'>
      <pose relative_to='left_arm_joint'>0 0 0 0 0 0</pose>
      <inertial>
        <pose>-0.0033583150583061938 0.075981037628964868 -0.02475935270819642 0 0 0</pose>
        <mass>0.089237025928972508</mass>
        <inertia>
          <ixx>0.00042099999999999999</ixx>
          <ixy>-9.8999999999999994e-05</ixy>
          <ixz>0</ixz>
          <iyy>0.00013100000000000001</iyy>
          <iyz>0</iyz>
          <izz>0.00047600000000000002</izz>
        </inertia>
      </inertial>
            <visual name='left_arm_1_visual'>
        <pose>-0.57499999999999996 -0.035000000000000003 -0.0060000000000000001 0 0 0</pose>
        <geometry>
          <mesh>
            <scale>0.001 0.001 0.001</scale>
            <uri>model://jumping_spider/meshes/left_arm_1.stl</uri>
          </mesh>
        </geometry>
        <material>
          <diffuse>0 0 0 1</diffuse>
          <ambient>0 0 0 1</ambient>
        </material>
      </visual>
    </link>
    <joint name='left_yaw_joint' type='revolute'>
      <pose relative_to='left_arm_1'>0.044406000000000001 0.19500799999999999 -0.0042500000000000003 0 0 0</pose>
      <parent>left_arm_1</parent>
      <child>left_yaw_link_1</child>
      <axis>
        <xyz>0 0 -1</xyz>
        <limit>
          <lower>-inf</lower>
          <upper>inf</upper>
        </limit>
        <dynamics>
          <spring_reference>0</spring_reference>
          <spring_stiffness>20</spring_stiffness>
<damping>1</damping>
        </dynamics>
      </axis>
    </joint>
    <link name='left_yaw_link_1'>
      <pose relative_to='left_yaw_joint'>0 0 0 0 0 0</pose>
      <inertial>
        <pose>7.2060683087293853e-08 -5.0675186130666461e-08 -0.019000033573863168 0 0 0</pose>
        <mass>0.0044710574988722652</mass>
        <inertia>
          <ixx>9.9999999999999995e-07</ixx>
          <ixy>0</ixy>
          <ixz>0</ixz>
          <iyy>9.9999999999999995e-07</iyy>
          <iyz>0</iyz>
          <izz>9.9999999999999995e-07</izz>
        </inertia>
      </inertial>
            <visual name='left_yaw_link_1_visual'>
        <pose>-0.61940600000000001 -0.23000799999999999 -0.00175 0 0 0</pose>
        <geometry>
          <mesh>
            <scale>0.001 0.001 0.001</scale>
            <uri>model://jumping_spider/meshes/left_yaw_link_1.stl</uri>
          </mesh>
        </geometry>
        <material>
          <diffuse>0 0 1 1</diffuse>
          <ambient>0 0 0 1</ambient>
        </material>
      </visual>
    </link>
    <joint name='left_pitch_joint' type='revolute'>
      <pose relative_to='left_yaw_link_1'>0 0.014250000000000001 -0.019 0 0 0</pose>
      <parent>left_yaw_link_1</parent>
      <child>left_pitch_link_1</child>
      <axis>
        <xyz>1.2e-05 -1 0</xyz>
        <limit>
          <lower>-inf</lower>
          <upper>inf</upper>
        </limit>
        <dynamics>
          <spring_reference>0</spring_reference>
          <spring_stiffness>20</spring_stiffness>
<damping>1</damping>
        </dynamics>
      </axis>
    </joint>
    <link name='left_pitch_link_1'>
      <pose relative_to='left_pitch_joint'>0 0 0 0 0 0</pose>
      <inertial>
        <pose>0.016410818993840112 -0.01399991315381219 -2.8597125140139571e-08 0 0 0</pose>
        <mass>0.053647535777609869</mass>
        <inertia>
          <ixx>3.4e-05</ixx>
          <ixy>0</ixy>
          <ixz>0</ixz>
          <iyy>2.8e-05</iyy>
          <iyz>0</iyz>
          <izz>2.8e-05</izz>
        </inertia>
      </inertial>
      <collision name='left_suction_collision'>
        <pose>0.03 -0.01 0 0 1.570795 0</pose>
            <geometry>
                <cylinder>
                    <length>0.01</length>
                    <radius>0.0455</radius>
                </cylinder>
            </geometry>
            <surface>
                <friction>
                    <ode>
                        <mu>
                            50.0
                        </mu>
                        <mu2>
                            50.0
                        </mu2>
                    </ode>
                </friction>
                <contact>
                    <ode>
                    <max_vel>0</max_vel>
                    <min_depth>0.001</min_depth>
                    </ode>
                </contact>
                </surface>
        </collision>
        <sensor name='sensor_contact' type='contact'>
            <contact>
                <collision>left_suction_collision</collision>
            </contact>
        </sensor>
            <visual name='left_pitch_link_1_visual'>
        <pose>-0.61940600000000001 -0.244258 0.017250000000000001 0 0 0</pose>
        <geometry>
          <mesh>
            <scale>0.001 0.001 0.001</scale>
            <uri>model://jumping_spider/meshes/left_pitch_link_1.stl</uri>
          </mesh>
        </geometry>
        <material>
          <diffuse>1 0 0 1</diffuse>
          <ambient>0 0 0 1</ambient>
        </material>
      </visual>
    </link>
    <joint name='gimbal_roll_joint' type='revolute'>
      <pose relative_to='base_link'>0.032500000000000001 0 0.237535 0 0 0</pose>
      <parent>base_link</parent>
      <child>gimbal_roll_1</child>
      <axis>
        <xyz>-1 0 0</xyz>
        <limit>
          <lower>-inf</lower>
          <upper>inf</upper>
        </limit>
        <dynamics>
          <spring_reference>0</spring_reference>
          <spring_stiffness>20</spring_stiffness>
<damping>1</damping>
        </dynamics>
      </axis>
    </joint>
    <link name='gimbal_roll_1'>
      <pose relative_to='gimbal_roll_joint'>0 0 0 0 0 0</pose>
      <inertial>
        <pose>0.025655883844864689 -0.003957377189178218 -0.00050379339257070055 0 0 0</pose>
        <mass>0.017714817282487669</mass>
        <inertia>
          <ixx>6.0000000000000002e-06</ixx>
          <ixy>-9.9999999999999995e-07</ixy>
          <ixz>0</ixz>
          <iyy>6.9999999999999999e-06</iyy>
          <iyz>0</iyz>
          <izz>1.2e-05</izz>
        </inertia>
      </inertial>
            <visual name='gimbal_roll_1_visual'>
        <pose>-0.032500000000000001 0 -0.237535 0 0 0</pose>
        <geometry>
          <mesh>
            <scale>0.001 0.001 0.001</scale>
            <uri>model://jumping_spider/meshes/gimbal_roll_1.stl</uri>
          </mesh>
        </geometry>
        <material>
          <diffuse>0 0 0 1</diffuse>
          <ambient>0 0 0 1</ambient>
        </material>
      </visual>
    </link>
    <joint name='gimbal_pitch_joint' type='revolute'>
      <pose relative_to='gimbal_roll_1'>0.077499999999999999 -0.028500000000000001 0.00014999999999999999 0 0 0</pose>
      <parent>gimbal_roll_1</parent>
      <child>gimbal_pitch_1</child>
      <axis>
        <xyz>0 -1 0</xyz>
        <limit>
          <lower>-inf</lower>
          <upper>inf</upper>
        </limit>
        <dynamics>
          <spring_reference>0</spring_reference>
          <spring_stiffness>20</spring_stiffness>
<damping>1</damping>
        </dynamics>
      </axis>
    </joint>
    <link name='gimbal_pitch_1'>
      <pose relative_to='gimbal_pitch_joint'>0 0 0 0 0 0</pose>
      <inertial>
        <pose>-0.0011807057318703319 0.029901559221687881 0.017311002256869521 0 0 0</pose>
        <mass>0.031890731763421068</mass>
        <inertia>
          <ixx>1.5999999999999999e-05</ixx>
          <ixy>9.9999999999999995e-07</ixy>
          <ixz>-1.9999999999999999e-06</ixz>
          <iyy>1.5e-05</iyy>
          <iyz>3.0000000000000001e-06</iyz>
          <izz>1.2e-05</izz>
        </inertia>
      </inertial>
            <visual name='gimbal_pitch_1_visual'>
        <pose>-0.11 0.028500000000000001 -0.23768500000000001 0 0 0</pose>
        <geometry>
          <mesh>
            <scale>0.001 0.001 0.001</scale>
            <uri>model://jumping_spider/meshes/gimbal_pitch_1.stl</uri>
          </mesh>
        </geometry>
        <material>
          <diffuse>0 0 0 1</diffuse>
          <ambient>0 0 0 1</ambient>
        </material>
      </visual>
       <sensor name='lidar' type='gpu_lidar'>
        <!-- <gz_frame_id>gimbal_pitch_1</gz_frame_id> -->
        <!-- <index>1</index> -->
        <pose degrees="true">0 0 0.03 0 0 0</pose>
        <always_on>1</always_on>
        <topic>lidar</topic>
        <update_rate>2</update_rate>
        <visualize>1</visualize>
        <ray>
          <scan>
            <horizontal>
              <samples>256</samples>
              <resolution>1</resolution>
              <min_angle>-2.9753</min_angle>
              <max_angle>2.9753</max_angle>
            </horizontal>
            <vertical>
              <samples>1</samples>
              <resolution>1</resolution>
              <min_angle >0</min_angle>
              <max_angle>0</max_angle>
            </vertical>
          </scan>
          <range>
            <min>0.1</min>
            <max>20</max>
            <resolution>0.05</resolution>
          </range>
          <noise>
            <type>gaussian</type>
            <mean>0</mean>
            <stddev>0.00</stddev>
          </noise>
        </ray>
      </sensor>
    </link>
        <plugin filename="SuctionPlugin"
            name="SuctionPlugin">
        <parent_link>right_pitch_link_1</parent_link>
        <detach_topic>/detach</detach_topic>
        <attach_topic>/attach</attach_topic>
        <output_topic>/attached_state</output_topic>
        <suction_force>100</suction_force>
        <leg_topic>/cmd_leg_pos</leg_topic>
        <leg_retracted_pos>0</leg_retracted_pos>
        <leg_extended_pos>1.5</leg_extended_pos>
    </plugin>
    <plugin filename="SuctionPlugin"
            name="SuctionPlugin">
        <parent_link>left_pitch_link_1</parent_link>
        <detach_topic>/detach</detach_topic>
        <attach_topic>/attach</attach_topic>
        <output_topic>/attached_state_2</output_topic>
        <suction_force>100</suction_force>
    </plugin>
  </model>
</sdf>